Workbook

Sheet Lisez-moi
A1: Comparatif des fonctionnalités CMS
A2: Analyse réalisée le 25 octobre 2026 à partir de la documentation officielle de chaque CMS. Base de travail pour concevoir un CMS Laravel / Filament.
A4: Onglets
A5: Synthèse | B5: Couverture par CMS et par catégorie (formules calculées depuis la Matrice)
A6: Priorisation | B6: Grille enrichie (grille + ajouts hors grille) classée MVP / V1 / V2, avec différenciants et briques Laravel/Filament
A7: Matrice | B7: 211 fonctionnalités × CMS, statut coloré. Filtrable.
A8: Détails | B8: Une ligne par fonctionnalité et par CMS : statut, explication, source
A9: Hors grille | B9: Fonctionnalités relevées en dehors de la grille — pistes d'ajout
A10: Inspirations | B10: Points forts, idées à reprendre et limites de chaque CMS
A12: Légende des statuts
A13: Natif | B13: Inclus dans le cœur, sans extension
A14: Officiel | B14: Extension, add-on ou édition de l'éditeur du CMS (« Payant : » dans le détail si payant)
A15: Tiers | B15: Uniquement via une extension tierce
A16: Partiel | B16: Existe mais limité (voir le détail)
A17: Absent | B17: N'existe pas, même via extension connue
A18: ? | B18: Non confirmé après recherche
A19: Info | B19: Réponse factuelle (licence, moteur, popularité…), voir Détails
A21: CMS analysés
A22: CMS | B22: Version analysée | C22: Licence | D22: Stack
A23: WordPress | B23: 7.1.3 (6 octobre 2026) | C23: GPLv2 ou ultérieure | D23: PHP 7.4+ (8.3+ recommandé) / pas de framework (API maison), React pour l'éditeur / MySQL ou MariaDB
A24: Drupal | B24: Drupal core 11.4.11 (octobre 2026) ; Drupal CMS 2.2.7 (23 octobre 2026) ; Canvas 1.12 | C24: GPL-2.0-or-later | D24: PHP 8.3+ / Symfony 7 + Twig / MySQL-MariaDB, PostgreSQL, SQLite
A25: Craft CMS | B25: 5.11.5.1 (8 octobre 2026) | C25: Craft License (propriétaire, source disponible) ; édition Solo gratuite, Team/Pro payantes | D25: PHP 8.2+ / Yii 2 / Twig / MySQL, MariaDB ou PostgreSQL ; panneau en JS/Vue
A26: Kirby | B26: 5.6.1 (6 octobre 2026) ; 6.0.0-beta.1 en test | C26: Propriétaire (code source public), licence payante par site : Basic 99 €, Enterprise 349 € | D26: PHP 8.2-8.5 / framework maison (Panel Vue 2→3) / flat-file (fichiers texte), Db MySQL/SQLite optionnelle
A27: Statamic | B27: 6.38.0 (23 octobre 2026) | C27: Core gratuit (licence propriétaire Statamic LLC, code source ouvert) ; Pro commercial 349 $/site | D27: PHP 8.3+ / Laravel 12-13 / flat-file (YAML/Markdown, Stache) ou base SQL via Eloquent Driver ; CP Vue 3 + Inertia + Tailwind 4
A28: October CMS | B28: 4.4.11 (12 octobre 2026) | C28: Propriétaire (EULA Responsiv Pty Ltd), code source public ; licence gratuite la 1re année puis 39 $/site/an pour les mises à jour | D28: PHP 8.2+ / Laravel 12 / Twig 3 / MySQL, MariaDB, PostgreSQL, SQLite ; backend Vue 3
A29: Grav | B29: 2.2.13 (23 octobre 2026) | C29: MIT | D29: PHP 8.3+ / composants Symfony 7, Twig 3 / flat-file (Markdown + YAML), sans base de données ; Admin2 en SvelteKit
A30: Payload | B30: 3.92.0 (22 octobre 2026) | C30: MIT (cœur et plugins @payloadcms/*) ; fonctions Enterprise commerciales | D30: TypeScript / Node.js, Next.js (React) / MongoDB, PostgreSQL, SQLite, Cloudflare D1
A31: TallCMS | B31: 4.9.1 (21 septembre 2026) | C31: MIT (Core) ; Pro, Multisite et Billing sous licence commerciale | D31: PHP 8.2+ / Laravel 12-13, Filament 5, Livewire 4, Tailwind v4 + daisyUI / MySQL, MariaDB, SQLite
A32: Lara Zeus Sky | B32: 5.0.1 (29 avril 2026) | C32: MIT | D32: PHP 8.2+ / Laravel + Filament 5 (TALL : Livewire, Alpine, Tailwind) / base relationnelle via Eloquent
A34: Note : les statuts reflètent la documentation consultée à la date d'analyse. Les projets jeunes (TallCMS, Sky) comportent davantage de « ? ». Vérifier les points décisifs avant de s'en servir.

Sheet Synthèse
A1: Synthèse de couverture
A2: Toutes les valeurs sont calculées depuis l'onglet Matrice.
A4: CMS | B4: Natif | C4: Officiel | D4: Tiers | E4: Partiel | F4: Absent | G4: ? | H4: Info | I4: Total | J4: % disponible (natif+officiel) | K4: % avec extension (natif+off.+tiers)
A5: WordPress | B5: =COUNTIF(Matrice!$D$2:$D$212,"Natif") -> 81 | C5: =COUNTIF(Matrice!$D$2:$D$212,"Officiel") -> 49 | D5: =COUNTIF(Matrice!$D$2:$D$212,"Tiers") -> 30 | E5: =COUNTIF(Matrice!$D$2:$D$212,"Partiel") -> 39 | F5: =COUNTIF(Matrice!$D$2:$D$212,"Absent") -> 2 | G5: =COUNTIF(Matrice!$D$2:$D$212,"?") -> 0 | H5: =COUNTIF(Matrice!$D$2:$D$212,"Info") -> 10 | I5: =SUM(B5:H5) -> 211 | J5: =IFERROR((B5+C5)/(I5-H5),0) -> 0.64676617 | K5: =IFERROR((B5+C5+D5)/(I5-H5),0) -> 0.7960199
A6: Drupal | B6: =COUNTIF(Matrice!$E$2:$E$212,"Natif") -> 87 | C6: =COUNTIF(Matrice!$E$2:$E$212,"Officiel") -> 11 | D6: =COUNTIF(Matrice!$E$2:$E$212,"Tiers") -> 67 | E6: =COUNTIF(Matrice!$E$2:$E$212,"Partiel") -> 34 | F6: =COUNTIF(Matrice!$E$2:$E$212,"Absent") -> 2 | G6: =COUNTIF(Matrice!$E$2:$E$212,"?") -> 0 | H6: =COUNTIF(Matrice!$E$2:$E$212,"Info") -> 10 | I6: =SUM(B6:H6) -> 211 | J6: =IFERROR((B6+C6)/(I6-H6),0) -> 0.48756219 | K6: =IFERROR((B6+C6+D6)/(I6-H6),0) -> 0.82089552
A7: Craft CMS | B7: =COUNTIF(Matrice!$F$2:$F$212,"Natif") -> 95 | C7: =COUNTIF(Matrice!$F$2:$F$212,"Officiel") -> 26 | D7: =COUNTIF(Matrice!$F$2:$F$212,"Tiers") -> 34 | E7: =COUNTIF(Matrice!$F$2:$F$212,"Partiel") -> 28 | F7: =COUNTIF(Matrice!$F$2:$F$212,"Absent") -> 18 | G7: =COUNTIF(Matrice!$F$2:$F$212,"?") -> 0 | H7: =COUNTIF(Matrice!$F$2:$F$212,"Info") -> 10 | I7: =SUM(B7:H7) -> 211 | J7: =IFERROR((B7+C7)/(I7-H7),0) -> 0.60199005 | K7: =IFERROR((B7+C7+D7)/(I7-H7),0) -> 0.77114428
A8: Kirby | B8: =COUNTIF(Matrice!$G$2:$G$212,"Natif") -> 74 | C8: =COUNTIF(Matrice!$G$2:$G$212,"Officiel") -> 6 | D8: =COUNTIF(Matrice!$G$2:$G$212,"Tiers") -> 52 | E8: =COUNTIF(Matrice!$G$2:$G$212,"Partiel") -> 47 | F8: =COUNTIF(Matrice!$G$2:$G$212,"Absent") -> 22 | G8: =COUNTIF(Matrice!$G$2:$G$212,"?") -> 0 | H8: =COUNTIF(Matrice!$G$2:$G$212,"Info") -> 10 | I8: =SUM(B8:H8) -> 211 | J8: =IFERROR((B8+C8)/(I8-H8),0) -> 0.39800995 | K8: =IFERROR((B8+C8+D8)/(I8-H8),0) -> 0.65671642
A9: Statamic | B9: =COUNTIF(Matrice!$H$2:$H$212,"Natif") -> 100 | C9: =COUNTIF(Matrice!$H$2:$H$212,"Officiel") -> 40 | D9: =COUNTIF(Matrice!$H$2:$H$212,"Tiers") -> 19 | E9: =COUNTIF(Matrice!$H$2:$H$212,"Partiel") -> 19 | F9: =COUNTIF(Matrice!$H$2:$H$212,"Absent") -> 21 | G9: =COUNTIF(Matrice!$H$2:$H$212,"?") -> 2 | H9: =COUNTIF(Matrice!$H$2:$H$212,"Info") -> 10 | I9: =SUM(B9:H9) -> 211 | J9: =IFERROR((B9+C9)/(I9-H9),0) -> 0.69651741 | K9: =IFERROR((B9+C9+D9)/(I9-H9),0) -> 0.79104478
A10: October CMS | B10: =COUNTIF(Matrice!$I$2:$I$212,"Natif") -> 98 | C10: =COUNTIF(Matrice!$I$2:$I$212,"Officiel") -> 11 | D10: =COUNTIF(Matrice!$I$2:$I$212,"Tiers") -> 15 | E10: =COUNTIF(Matrice!$I$2:$I$212,"Partiel") -> 51 | F10: =COUNTIF(Matrice!$I$2:$I$212,"Absent") -> 23 | G10: =COUNTIF(Matrice!$I$2:$I$212,"?") -> 3 | H10: =COUNTIF(Matrice!$I$2:$I$212,"Info") -> 10 | I10: =SUM(B10:H10) -> 211 | J10: =IFERROR((B10+C10)/(I10-H10),0) -> 0.54228856 | K10: =IFERROR((B10+C10+D10)/(I10-H10),0) -> 0.61691542
A11: Grav | B11: =COUNTIF(Matrice!$J$2:$J$212,"Natif") -> 68 | C11: =COUNTIF(Matrice!$J$2:$J$212,"Officiel") -> 61 | D11: =COUNTIF(Matrice!$J$2:$J$212,"Tiers") -> 5 | E11: =COUNTIF(Matrice!$J$2:$J$212,"Partiel") -> 38 | F11: =COUNTIF(Matrice!$J$2:$J$212,"Absent") -> 24 | G11: =COUNTIF(Matrice!$J$2:$J$212,"?") -> 5 | H11: =COUNTIF(Matrice!$J$2:$J$212,"Info") -> 10 | I11: =SUM(B11:H11) -> 211 | J11: =IFERROR((B11+C11)/(I11-H11),0) -> 0.64179104 | K11: =IFERROR((B11+C11+D11)/(I11-H11),0) -> 0.66666667
A12: Payload | B12: =COUNTIF(Matrice!$K$2:$K$212,"Natif") -> 88 | C12: =COUNTIF(Matrice!$K$2:$K$212,"Officiel") -> 29 | D12: =COUNTIF(Matrice!$K$2:$K$212,"Tiers") -> 2 | E12: =COUNTIF(Matrice!$K$2:$K$212,"Partiel") -> 45 | F12: =COUNTIF(Matrice!$K$2:$K$212,"Absent") -> 37 | G12: =COUNTIF(Matrice!$K$2:$K$212,"?") -> 0 | H12: =COUNTIF(Matrice!$K$2:$K$212,"Info") -> 10 | I12: =SUM(B12:H12) -> 211 | J12: =IFERROR((B12+C12)/(I12-H12),0) -> 0.58208955 | K12: =IFERROR((B12+C12+D12)/(I12-H12),0) -> 0.5920398
A13: TallCMS | B13: =COUNTIF(Matrice!$L$2:$L$212,"Natif") -> 86 | C13: =COUNTIF(Matrice!$L$2:$L$212,"Officiel") -> 9 | D13: =COUNTIF(Matrice!$L$2:$L$212,"Tiers") -> 4 | E13: =COUNTIF(Matrice!$L$2:$L$212,"Partiel") -> 52 | F13: =COUNTIF(Matrice!$L$2:$L$212,"Absent") -> 47 | G13: =COUNTIF(Matrice!$L$2:$L$212,"?") -> 3 | H13: =COUNTIF(Matrice!$L$2:$L$212,"Info") -> 10 | I13: =SUM(B13:H13) -> 211 | J13: =IFERROR((B13+C13)/(I13-H13),0) -> 0.47263682 | K13: =IFERROR((B13+C13+D13)/(I13-H13),0) -> 0.49253731
A14: Lara Zeus Sky | B14: =COUNTIF(Matrice!$M$2:$M$212,"Natif") -> 52 | C14: =COUNTIF(Matrice!$M$2:$M$212,"Officiel") -> 8 | D14: =COUNTIF(Matrice!$M$2:$M$212,"Tiers") -> 6 | E14: =COUNTIF(Matrice!$M$2:$M$212,"Partiel") -> 45 | F14: =COUNTIF(Matrice!$M$2:$M$212,"Absent") -> 86 | G14: =COUNTIF(Matrice!$M$2:$M$212,"?") -> 4 | H14: =COUNTIF(Matrice!$M$2:$M$212,"Info") -> 10 | I14: =SUM(B14:H14) -> 211 | J14: =IFERROR((B14+C14)/(I14-H14),0) -> 0.29850746 | K14: =IFERROR((B14+C14+D14)/(I14-H14),0) -> 0.32835821
A15: « % disponible » exclut les lignes Info du dénominateur.
A17: Disponibilité (natif + officiel) par catégorie
A18: Bloc | B18: Catégorie | C18: Nb fonct. | D18: WordPress | E18: Drupal | F18: Craft CMS | G18: Kirby | H18: Statamic | I18: October CMS | J18: Grav | K18: Payload | L18: TallCMS | M18: Lara Zeus Sky
A19: Contenu | B19: Modélisation de contenu | C19: 13 | D19: =IFERROR((COUNTIF(Matrice!$D$2:$D$14,"Natif")+COUNTIF(Matrice!$D$2:$D$14,"Officiel"))/(C19-COUNTIF(Matrice!$D$2:$D$14,"Info")),0) -> 0.92307692 | E19: =IFERROR((COUNTIF(Matrice!$E$2:$E$14,"Natif")+COUNTIF(Matrice!$E$2:$E$14,"Officiel"))/(C19-COUNTIF(Matrice!$E$2:$E$14,"Info")),0) -> 0.46153846 | F19: =IFERROR((COUNTIF(Matrice!$F$2:$F$14,"Natif")+COUNTIF(Matrice!$F$2:$F$14,"Officiel"))/(C19-COUNTIF(Matrice!$F$2:$F$14,"Info")),0) -> 0.92307692 | G19: =IFERROR((COUNTIF(Matrice!$G$2:$G$14,"Natif")+COUNTIF(Matrice!$G$2:$G$14,"Officiel"))/(C19-COUNTIF(Matrice!$G$2:$G$14,"Info")),0) -> 0.61538462 | H19: =IFERROR((COUNTIF(Matrice!$H$2:$H$14,"Natif")+COUNTIF(Matrice!$H$2:$H$14,"Officiel"))/(C19-COUNTIF(Matrice!$H$2:$H$14,"Info")),0) -> 0.92307692 | I19: =IFERROR((COUNTIF(Matrice!$I$2:$I$14,"Natif")+COUNTIF(Matrice!$I$2:$I$14,"Officiel"))/(C19-COUNTIF(Matrice!$I$2:$I$14,"Info")),0) -> 0.76923077 | J19: =IFERROR((COUNTIF(Matrice!$J$2:$J$14,"Natif")+COUNTIF(Matrice!$J$2:$J$14,"Officiel"))/(C19-COUNTIF(Matrice!$J$2:$J$14,"Info")),0) -> 0.61538462 | K19: =IFERROR((COUNTIF(Matrice!$K$2:$K$14,"Natif")+COUNTIF(Matrice!$K$2:$K$14,"Officiel"))/(C19-COUNTIF(Matrice!$K$2:$K$14,"Info")),0) -> 0.84615385 | L19: =IFERROR((COUNTIF(Matrice!$L$2:$L$14,"Natif")+COUNTIF(Matrice!$L$2:$L$14,"Officiel"))/(C19-COUNTIF(Matrice!$L$2:$L$14,"Info")),0) -> 0.30769231 | M19: =IFERROR((COUNTIF(Matrice!$M$2:$M$14,"Natif")+COUNTIF(Matrice!$M$2:$M$14,"Officiel"))/(C19-COUNTIF(Matrice!$M$2:$M$14,"Info")),0) -> 0.23076923
A20: Contenu | B20: Édition et blocs | C20: 11 | D20: =IFERROR((COUNTIF(Matrice!$D$15:$D$25,"Natif")+COUNTIF(Matrice!$D$15:$D$25,"Officiel"))/(C20-COUNTIF(Matrice!$D$15:$D$25,"Info")),0) -> 0.81818182 | E20: =IFERROR((COUNTIF(Matrice!$E$15:$E$25,"Natif")+COUNTIF(Matrice!$E$15:$E$25,"Officiel"))/(C20-COUNTIF(Matrice!$E$15:$E$25,"Info")),0) -> 0.81818182 | F20: =IFERROR((COUNTIF(Matrice!$F$15:$F$25,"Natif")+COUNTIF(Matrice!$F$15:$F$25,"Officiel"))/(C20-COUNTIF(Matrice!$F$15:$F$25,"Info")),0) -> 0.63636364 | G20: =IFERROR((COUNTIF(Matrice!$G$15:$G$25,"Natif")+COUNTIF(Matrice!$G$15:$G$25,"Officiel"))/(C20-COUNTIF(Matrice!$G$15:$G$25,"Info")),0) -> 0.63636364 | H20: =IFERROR((COUNTIF(Matrice!$H$15:$H$25,"Natif")+COUNTIF(Matrice!$H$15:$H$25,"Officiel"))/(C20-COUNTIF(Matrice!$H$15:$H$25,"Info")),0) -> 0.63636364 | I20: =IFERROR((COUNTIF(Matrice!$I$15:$I$25,"Natif")+COUNTIF(Matrice!$I$15:$I$25,"Officiel"))/(C20-COUNTIF(Matrice!$I$15:$I$25,"Info")),0) -> 0.54545455 | J20: =IFERROR((COUNTIF(Matrice!$J$15:$J$25,"Natif")+COUNTIF(Matrice!$J$15:$J$25,"Officiel"))/(C20-COUNTIF(Matrice!$J$15:$J$25,"Info")),0) -> 0.63636364 | K20: =IFERROR((COUNTIF(Matrice!$K$15:$K$25,"Natif")+COUNTIF(Matrice!$K$15:$K$25,"Officiel"))/(C20-COUNTIF(Matrice!$K$15:$K$25,"Info")),0) -> 0.90909091 | L20: =IFERROR((COUNTIF(Matrice!$L$15:$L$25,"Natif")+COUNTIF(Matrice!$L$15:$L$25,"Officiel"))/(C20-COUNTIF(Matrice!$L$15:$L$25,"Info")),0) -> 0.45454545 | M20: =IFERROR((COUNTIF(Matrice!$M$15:$M$25,"Natif")+COUNTIF(Matrice!$M$15:$M$25,"Officiel"))/(C20-COUNTIF(Matrice!$M$15:$M$25,"Info")),0) -> 0.27272727
A21: Contenu | B21: Médias | C21: 10 | D21: =IFERROR((COUNTIF(Matrice!$D$26:$D$35,"Natif")+COUNTIF(Matrice!$D$26:$D$35,"Officiel"))/(C21-COUNTIF(Matrice!$D$26:$D$35,"Info")),0) -> 0.5 | E21: =IFERROR((COUNTIF(Matrice!$E$26:$E$35,"Natif")+COUNTIF(Matrice!$E$26:$E$35,"Officiel"))/(C21-COUNTIF(Matrice!$E$26:$E$35,"Info")),0) -> 0.5 | F21: =IFERROR((COUNTIF(Matrice!$F$26:$F$35,"Natif")+COUNTIF(Matrice!$F$26:$F$35,"Officiel"))/(C21-COUNTIF(Matrice!$F$26:$F$35,"Info")),0) -> 0.9 | G21: =IFERROR((COUNTIF(Matrice!$G$26:$G$35,"Natif")+COUNTIF(Matrice!$G$26:$G$35,"Officiel"))/(C21-COUNTIF(Matrice!$G$26:$G$35,"Info")),0) -> 0.6 | H21: =IFERROR((COUNTIF(Matrice!$H$26:$H$35,"Natif")+COUNTIF(Matrice!$H$26:$H$35,"Officiel"))/(C21-COUNTIF(Matrice!$H$26:$H$35,"Info")),0) -> 0.9 | I21: =IFERROR((COUNTIF(Matrice!$I$26:$I$35,"Natif")+COUNTIF(Matrice!$I$26:$I$35,"Officiel"))/(C21-COUNTIF(Matrice!$I$26:$I$35,"Info")),0) -> 0.6 | J21: =IFERROR((COUNTIF(Matrice!$J$26:$J$35,"Natif")+COUNTIF(Matrice!$J$26:$J$35,"Officiel"))/(C21-COUNTIF(Matrice!$J$26:$J$35,"Info")),0) -> 0.7 | K21: =IFERROR((COUNTIF(Matrice!$K$26:$K$35,"Natif")+COUNTIF(Matrice!$K$26:$K$35,"Officiel"))/(C21-COUNTIF(Matrice!$K$26:$K$35,"Info")),0) -> 0.8 | L21: =IFERROR((COUNTIF(Matrice!$L$26:$L$35,"Natif")+COUNTIF(Matrice!$L$26:$L$35,"Officiel"))/(C21-COUNTIF(Matrice!$L$26:$L$35,"Info")),0) -> 0.4 | M21: =IFERROR((COUNTIF(Matrice!$M$26:$M$35,"Natif")+COUNTIF(Matrice!$M$26:$M$35,"Officiel"))/(C21-COUNTIF(Matrice!$M$26:$M$35,"Info")),0) -> 0.3
A22: Contenu | B22: Versioning et planification | C22: 8 | D22: =IFERROR((COUNTIF(Matrice!$D$36:$D$43,"Natif")+COUNTIF(Matrice!$D$36:$D$43,"Officiel"))/(C22-COUNTIF(Matrice!$D$36:$D$43,"Info")),0) -> 0.75 | E22: =IFERROR((COUNTIF(Matrice!$E$36:$E$43,"Natif")+COUNTIF(Matrice!$E$36:$E$43,"Officiel"))/(C22-COUNTIF(Matrice!$E$36:$E$43,"Info")),0) -> 0.375 | F22: =IFERROR((COUNTIF(Matrice!$F$36:$F$43,"Natif")+COUNTIF(Matrice!$F$36:$F$43,"Officiel"))/(C22-COUNTIF(Matrice!$F$36:$F$43,"Info")),0) -> 0.875 | G22: =IFERROR((COUNTIF(Matrice!$G$36:$G$43,"Natif")+COUNTIF(Matrice!$G$36:$G$43,"Officiel"))/(C22-COUNTIF(Matrice!$G$36:$G$43,"Info")),0) -> 0.25 | H22: =IFERROR((COUNTIF(Matrice!$H$36:$H$43,"Natif")+COUNTIF(Matrice!$H$36:$H$43,"Officiel"))/(C22-COUNTIF(Matrice!$H$36:$H$43,"Info")),0) -> 0.625 | I22: =IFERROR((COUNTIF(Matrice!$I$36:$I$43,"Natif")+COUNTIF(Matrice!$I$36:$I$43,"Officiel"))/(C22-COUNTIF(Matrice!$I$36:$I$43,"Info")),0) -> 0.625 | J22: =IFERROR((COUNTIF(Matrice!$J$36:$J$43,"Natif")+COUNTIF(Matrice!$J$36:$J$43,"Officiel"))/(C22-COUNTIF(Matrice!$J$36:$J$43,"Info")),0) -> 0.875 | K22: =IFERROR((COUNTIF(Matrice!$K$36:$K$43,"Natif")+COUNTIF(Matrice!$K$36:$K$43,"Officiel"))/(C22-COUNTIF(Matrice!$K$36:$K$43,"Info")),0) -> 1 | L22: =IFERROR((COUNTIF(Matrice!$L$36:$L$43,"Natif")+COUNTIF(Matrice!$L$36:$L$43,"Officiel"))/(C22-COUNTIF(Matrice!$L$36:$L$43,"Info")),0) -> 0.75 | M22: =IFERROR((COUNTIF(Matrice!$M$36:$M$43,"Natif")+COUNTIF(Matrice!$M$36:$M$43,"Officiel"))/(C22-COUNTIF(Matrice!$M$36:$M$43,"Info")),0) -> 0.375
A23: Contenu | B23: Recherche | C23: 6 | D23: =IFERROR((COUNTIF(Matrice!$D$44:$D$49,"Natif")+COUNTIF(Matrice!$D$44:$D$49,"Officiel"))/(C23-COUNTIF(Matrice!$D$44:$D$49,"Info")),0) -> 0.66666667 | E23: =IFERROR((COUNTIF(Matrice!$E$44:$E$49,"Natif")+COUNTIF(Matrice!$E$44:$E$49,"Officiel"))/(C23-COUNTIF(Matrice!$E$44:$E$49,"Info")),0) -> 0.16666667 | F23: =IFERROR((COUNTIF(Matrice!$F$44:$F$49,"Natif")+COUNTIF(Matrice!$F$44:$F$49,"Officiel"))/(C23-COUNTIF(Matrice!$F$44:$F$49,"Info")),0) -> 0.66666667 | G23: =IFERROR((COUNTIF(Matrice!$G$44:$G$49,"Natif")+COUNTIF(Matrice!$G$44:$G$49,"Officiel"))/(C23-COUNTIF(Matrice!$G$44:$G$49,"Info")),0) -> 0.33333333 | H23: =IFERROR((COUNTIF(Matrice!$H$44:$H$49,"Natif")+COUNTIF(Matrice!$H$44:$H$49,"Officiel"))/(C23-COUNTIF(Matrice!$H$44:$H$49,"Info")),0) -> 0.83333333 | I23: =IFERROR((COUNTIF(Matrice!$I$44:$I$49,"Natif")+COUNTIF(Matrice!$I$44:$I$49,"Officiel"))/(C23-COUNTIF(Matrice!$I$44:$I$49,"Info")),0) -> 0.16666667 | J23: =IFERROR((COUNTIF(Matrice!$J$44:$J$49,"Natif")+COUNTIF(Matrice!$J$44:$J$49,"Officiel"))/(C23-COUNTIF(Matrice!$J$44:$J$49,"Info")),0) -> 0.83333333 | K23: =IFERROR((COUNTIF(Matrice!$K$44:$K$49,"Natif")+COUNTIF(Matrice!$K$44:$K$49,"Officiel"))/(C23-COUNTIF(Matrice!$K$44:$K$49,"Info")),0) -> 0.66666667 | L23: =IFERROR((COUNTIF(Matrice!$L$44:$L$49,"Natif")+COUNTIF(Matrice!$L$44:$L$49,"Officiel"))/(C23-COUNTIF(Matrice!$L$44:$L$49,"Info")),0) -> 0.33333333 | M23: =IFERROR((COUNTIF(Matrice!$M$44:$M$49,"Natif")+COUNTIF(Matrice!$M$44:$M$49,"Officiel"))/(C23-COUNTIF(Matrice!$M$44:$M$49,"Info")),0) -> 0.33333333
A24: Contenu | B24: Formulaires | C24: 7 | D24: =IFERROR((COUNTIF(Matrice!$D$50:$D$56,"Natif")+COUNTIF(Matrice!$D$50:$D$56,"Officiel"))/(C24-COUNTIF(Matrice!$D$50:$D$56,"Info")),0) -> 1 | E24: =IFERROR((COUNTIF(Matrice!$E$50:$E$56,"Natif")+COUNTIF(Matrice!$E$50:$E$56,"Officiel"))/(C24-COUNTIF(Matrice!$E$50:$E$56,"Info")),0) -> 0 | F24: =IFERROR((COUNTIF(Matrice!$F$50:$F$56,"Natif")+COUNTIF(Matrice!$F$50:$F$56,"Officiel"))/(C24-COUNTIF(Matrice!$F$50:$F$56,"Info")),0) -> 0.42857143 | G24: =IFERROR((COUNTIF(Matrice!$G$50:$G$56,"Natif")+COUNTIF(Matrice!$G$50:$G$56,"Officiel"))/(C24-COUNTIF(Matrice!$G$50:$G$56,"Info")),0) -> 0 | H24: =IFERROR((COUNTIF(Matrice!$H$50:$H$56,"Natif")+COUNTIF(Matrice!$H$50:$H$56,"Officiel"))/(C24-COUNTIF(Matrice!$H$50:$H$56,"Info")),0) -> 1 | I24: =IFERROR((COUNTIF(Matrice!$I$50:$I$56,"Natif")+COUNTIF(Matrice!$I$50:$I$56,"Officiel"))/(C24-COUNTIF(Matrice!$I$50:$I$56,"Info")),0) -> 0.71428571 | J24: =IFERROR((COUNTIF(Matrice!$J$50:$J$56,"Natif")+COUNTIF(Matrice!$J$50:$J$56,"Officiel"))/(C24-COUNTIF(Matrice!$J$50:$J$56,"Info")),0) -> 0.57142857 | K24: =IFERROR((COUNTIF(Matrice!$K$50:$K$56,"Natif")+COUNTIF(Matrice!$K$50:$K$56,"Officiel"))/(C24-COUNTIF(Matrice!$K$50:$K$56,"Info")),0) -> 0.71428571 | L24: =IFERROR((COUNTIF(Matrice!$L$50:$L$56,"Natif")+COUNTIF(Matrice!$L$50:$L$56,"Officiel"))/(C24-COUNTIF(Matrice!$L$50:$L$56,"Info")),0) -> 0.28571429 | M24: =IFERROR((COUNTIF(Matrice!$M$50:$M$56,"Natif")+COUNTIF(Matrice!$M$50:$M$56,"Officiel"))/(C24-COUNTIF(Matrice!$M$50:$M$56,"Info")),0) -> 0.85714286
A25: Utilisateurs | B25: Utilisateurs et rôles | C25: 9 | D25: =IFERROR((COUNTIF(Matrice!$D$57:$D$65,"Natif")+COUNTIF(Matrice!$D$57:$D$65,"Officiel"))/(C25-COUNTIF(Matrice!$D$57:$D$65,"Info")),0) -> 0.44444444 | E25: =IFERROR((COUNTIF(Matrice!$E$57:$E$65,"Natif")+COUNTIF(Matrice!$E$57:$E$65,"Officiel"))/(C25-COUNTIF(Matrice!$E$57:$E$65,"Info")),0) -> 0.44444444 | F25: =IFERROR((COUNTIF(Matrice!$F$57:$F$65,"Natif")+COUNTIF(Matrice!$F$57:$F$65,"Officiel"))/(C25-COUNTIF(Matrice!$F$57:$F$65,"Info")),0) -> 1 | G25: =IFERROR((COUNTIF(Matrice!$G$57:$G$65,"Natif")+COUNTIF(Matrice!$G$57:$G$65,"Officiel"))/(C25-COUNTIF(Matrice!$G$57:$G$65,"Info")),0) -> 0.33333333 | H25: =IFERROR((COUNTIF(Matrice!$H$57:$H$65,"Natif")+COUNTIF(Matrice!$H$57:$H$65,"Officiel"))/(C25-COUNTIF(Matrice!$H$57:$H$65,"Info")),0) -> 0.88888889 | I25: =IFERROR((COUNTIF(Matrice!$I$57:$I$65,"Natif")+COUNTIF(Matrice!$I$57:$I$65,"Officiel"))/(C25-COUNTIF(Matrice!$I$57:$I$65,"Info")),0) -> 0.66666667 | J25: =IFERROR((COUNTIF(Matrice!$J$57:$J$65,"Natif")+COUNTIF(Matrice!$J$57:$J$65,"Officiel"))/(C25-COUNTIF(Matrice!$J$57:$J$65,"Info")),0) -> 0.77777778 | K25: =IFERROR((COUNTIF(Matrice!$K$57:$K$65,"Natif")+COUNTIF(Matrice!$K$57:$K$65,"Officiel"))/(C25-COUNTIF(Matrice!$K$57:$K$65,"Info")),0) -> 0.55555556 | L25: =IFERROR((COUNTIF(Matrice!$L$57:$L$65,"Natif")+COUNTIF(Matrice!$L$57:$L$65,"Officiel"))/(C25-COUNTIF(Matrice!$L$57:$L$65,"Info")),0) -> 0.44444444 | M25: =IFERROR((COUNTIF(Matrice!$M$57:$M$65,"Natif")+COUNTIF(Matrice!$M$57:$M$65,"Officiel"))/(C25-COUNTIF(Matrice!$M$57:$M$65,"Info")),0) -> 0.11111111
A26: Utilisateurs | B26: Workflows éditoriaux | C26: 6 | D26: =IFERROR((COUNTIF(Matrice!$D$66:$D$71,"Natif")+COUNTIF(Matrice!$D$66:$D$71,"Officiel"))/(C26-COUNTIF(Matrice!$D$66:$D$71,"Info")),0) -> 0.5 | E26: =IFERROR((COUNTIF(Matrice!$E$66:$E$71,"Natif")+COUNTIF(Matrice!$E$66:$E$71,"Officiel"))/(C26-COUNTIF(Matrice!$E$66:$E$71,"Info")),0) -> 0.33333333 | F26: =IFERROR((COUNTIF(Matrice!$F$66:$F$71,"Natif")+COUNTIF(Matrice!$F$66:$F$71,"Officiel"))/(C26-COUNTIF(Matrice!$F$66:$F$71,"Info")),0) -> 0 | G26: =IFERROR((COUNTIF(Matrice!$G$66:$G$71,"Natif")+COUNTIF(Matrice!$G$66:$G$71,"Officiel"))/(C26-COUNTIF(Matrice!$G$66:$G$71,"Info")),0) -> 0.16666667 | H26: =IFERROR((COUNTIF(Matrice!$H$66:$H$71,"Natif")+COUNTIF(Matrice!$H$66:$H$71,"Officiel"))/(C26-COUNTIF(Matrice!$H$66:$H$71,"Info")),0) -> 0.33333333 | I26: =IFERROR((COUNTIF(Matrice!$I$66:$I$71,"Natif")+COUNTIF(Matrice!$I$66:$I$71,"Officiel"))/(C26-COUNTIF(Matrice!$I$66:$I$71,"Info")),0) -> 0 | J26: =IFERROR((COUNTIF(Matrice!$J$66:$J$71,"Natif")+COUNTIF(Matrice!$J$66:$J$71,"Officiel"))/(C26-COUNTIF(Matrice!$J$66:$J$71,"Info")),0) -> 0.16666667 | K26: =IFERROR((COUNTIF(Matrice!$K$66:$K$71,"Natif")+COUNTIF(Matrice!$K$66:$K$71,"Officiel"))/(C26-COUNTIF(Matrice!$K$66:$K$71,"Info")),0) -> 0.83333333 | L26: =IFERROR((COUNTIF(Matrice!$L$66:$L$71,"Natif")+COUNTIF(Matrice!$L$66:$L$71,"Officiel"))/(C26-COUNTIF(Matrice!$L$66:$L$71,"Info")),0) -> 0.16666667 | M26: =IFERROR((COUNTIF(Matrice!$M$66:$M$71,"Natif")+COUNTIF(Matrice!$M$66:$M$71,"Officiel"))/(C26-COUNTIF(Matrice!$M$66:$M$71,"Info")),0) -> 0.16666667
A27: Utilisateurs | B27: Notifications et e-mails | C27: 5 | D27: =IFERROR((COUNTIF(Matrice!$D$72:$D$76,"Natif")+COUNTIF(Matrice!$D$72:$D$76,"Officiel"))/(C27-COUNTIF(Matrice!$D$72:$D$76,"Info")),0) -> 0.2 | E27: =IFERROR((COUNTIF(Matrice!$E$72:$E$76,"Natif")+COUNTIF(Matrice!$E$72:$E$76,"Officiel"))/(C27-COUNTIF(Matrice!$E$72:$E$76,"Info")),0) -> 0.2 | F27: =IFERROR((COUNTIF(Matrice!$F$72:$F$76,"Natif")+COUNTIF(Matrice!$F$72:$F$76,"Officiel"))/(C27-COUNTIF(Matrice!$F$72:$F$76,"Info")),0) -> 0.6 | G27: =IFERROR((COUNTIF(Matrice!$G$72:$G$76,"Natif")+COUNTIF(Matrice!$G$72:$G$76,"Officiel"))/(C27-COUNTIF(Matrice!$G$72:$G$76,"Info")),0) -> 0.2 | H27: =IFERROR((COUNTIF(Matrice!$H$72:$H$76,"Natif")+COUNTIF(Matrice!$H$72:$H$76,"Officiel"))/(C27-COUNTIF(Matrice!$H$72:$H$76,"Info")),0) -> 0.2 | I27: =IFERROR((COUNTIF(Matrice!$I$72:$I$76,"Natif")+COUNTIF(Matrice!$I$72:$I$76,"Officiel"))/(C27-COUNTIF(Matrice!$I$72:$I$76,"Info")),0) -> 0.8 | J27: =IFERROR((COUNTIF(Matrice!$J$72:$J$76,"Natif")+COUNTIF(Matrice!$J$72:$J$76,"Officiel"))/(C27-COUNTIF(Matrice!$J$72:$J$76,"Info")),0) -> 0.6 | K27: =IFERROR((COUNTIF(Matrice!$K$72:$K$76,"Natif")+COUNTIF(Matrice!$K$72:$K$76,"Officiel"))/(C27-COUNTIF(Matrice!$K$72:$K$76,"Info")),0) -> 0.4 | L27: =IFERROR((COUNTIF(Matrice!$L$72:$L$76,"Natif")+COUNTIF(Matrice!$L$72:$L$76,"Officiel"))/(C27-COUNTIF(Matrice!$L$72:$L$76,"Info")),0) -> 0.8 | M27: =IFERROR((COUNTIF(Matrice!$M$72:$M$76,"Natif")+COUNTIF(Matrice!$M$72:$M$76,"Officiel"))/(C27-COUNTIF(Matrice!$M$72:$M$76,"Info")),0) -> 0.2
A28: Diffusion | B28: Multilingue et multi-site | C28: 7 | D28: =IFERROR((COUNTIF(Matrice!$D$77:$D$83,"Natif")+COUNTIF(Matrice!$D$77:$D$83,"Officiel"))/(C28-COUNTIF(Matrice!$D$77:$D$83,"Info")),0) -> 0.28571429 | E28: =IFERROR((COUNTIF(Matrice!$E$77:$E$83,"Natif")+COUNTIF(Matrice!$E$77:$E$83,"Officiel"))/(C28-COUNTIF(Matrice!$E$77:$E$83,"Info")),0) -> 0.71428571 | F28: =IFERROR((COUNTIF(Matrice!$F$77:$F$83,"Natif")+COUNTIF(Matrice!$F$77:$F$83,"Officiel"))/(C28-COUNTIF(Matrice!$F$77:$F$83,"Info")),0) -> 0.71428571 | G28: =IFERROR((COUNTIF(Matrice!$G$77:$G$83,"Natif")+COUNTIF(Matrice!$G$77:$G$83,"Officiel"))/(C28-COUNTIF(Matrice!$G$77:$G$83,"Info")),0) -> 0.57142857 | H28: =IFERROR((COUNTIF(Matrice!$H$77:$H$83,"Natif")+COUNTIF(Matrice!$H$77:$H$83,"Officiel"))/(C28-COUNTIF(Matrice!$H$77:$H$83,"Info")),0) -> 0.85714286 | I28: =IFERROR((COUNTIF(Matrice!$I$77:$I$83,"Natif")+COUNTIF(Matrice!$I$77:$I$83,"Officiel"))/(C28-COUNTIF(Matrice!$I$77:$I$83,"Info")),0) -> 0.71428571 | J28: =IFERROR((COUNTIF(Matrice!$J$77:$J$83,"Natif")+COUNTIF(Matrice!$J$77:$J$83,"Officiel"))/(C28-COUNTIF(Matrice!$J$77:$J$83,"Info")),0) -> 0.42857143 | K28: =IFERROR((COUNTIF(Matrice!$K$77:$K$83,"Natif")+COUNTIF(Matrice!$K$77:$K$83,"Officiel"))/(C28-COUNTIF(Matrice!$K$77:$K$83,"Info")),0) -> 0.71428571 | L28: =IFERROR((COUNTIF(Matrice!$L$77:$L$83,"Natif")+COUNTIF(Matrice!$L$77:$L$83,"Officiel"))/(C28-COUNTIF(Matrice!$L$77:$L$83,"Info")),0) -> 0.85714286 | M28: =IFERROR((COUNTIF(Matrice!$M$77:$M$83,"Natif")+COUNTIF(Matrice!$M$77:$M$83,"Officiel"))/(C28-COUNTIF(Matrice!$M$77:$M$83,"Info")),0) -> 0.42857143
A29: Diffusion | B29: Routing | C29: 9 | D29: =IFERROR((COUNTIF(Matrice!$D$84:$D$92,"Natif")+COUNTIF(Matrice!$D$84:$D$92,"Officiel"))/(C29-COUNTIF(Matrice!$D$84:$D$92,"Info")),0) -> 0.55555556 | E29: =IFERROR((COUNTIF(Matrice!$E$84:$E$92,"Natif")+COUNTIF(Matrice!$E$84:$E$92,"Officiel"))/(C29-COUNTIF(Matrice!$E$84:$E$92,"Info")),0) -> 0.44444444 | F29: =IFERROR((COUNTIF(Matrice!$F$84:$F$92,"Natif")+COUNTIF(Matrice!$F$84:$F$92,"Officiel"))/(C29-COUNTIF(Matrice!$F$84:$F$92,"Info")),0) -> 0.55555556 | G29: =IFERROR((COUNTIF(Matrice!$G$84:$G$92,"Natif")+COUNTIF(Matrice!$G$84:$G$92,"Officiel"))/(C29-COUNTIF(Matrice!$G$84:$G$92,"Info")),0) -> 0.44444444 | H29: =IFERROR((COUNTIF(Matrice!$H$84:$H$92,"Natif")+COUNTIF(Matrice!$H$84:$H$92,"Officiel"))/(C29-COUNTIF(Matrice!$H$84:$H$92,"Info")),0) -> 1 | I29: =IFERROR((COUNTIF(Matrice!$I$84:$I$92,"Natif")+COUNTIF(Matrice!$I$84:$I$92,"Officiel"))/(C29-COUNTIF(Matrice!$I$84:$I$92,"Info")),0) -> 0.66666667 | J29: =IFERROR((COUNTIF(Matrice!$J$84:$J$92,"Natif")+COUNTIF(Matrice!$J$84:$J$92,"Officiel"))/(C29-COUNTIF(Matrice!$J$84:$J$92,"Info")),0) -> 0.66666667 | K29: =IFERROR((COUNTIF(Matrice!$K$84:$K$92,"Natif")+COUNTIF(Matrice!$K$84:$K$92,"Officiel"))/(C29-COUNTIF(Matrice!$K$84:$K$92,"Info")),0) -> 0.33333333 | L29: =IFERROR((COUNTIF(Matrice!$L$84:$L$92,"Natif")+COUNTIF(Matrice!$L$84:$L$92,"Officiel"))/(C29-COUNTIF(Matrice!$L$84:$L$92,"Info")),0) -> 0.44444444 | M29: =IFERROR((COUNTIF(Matrice!$M$84:$M$92,"Natif")+COUNTIF(Matrice!$M$84:$M$92,"Officiel"))/(C29-COUNTIF(Matrice!$M$84:$M$92,"Info")),0) -> 0.22222222
A30: Diffusion | B30: Templating | C30: 7 | D30: =IFERROR((COUNTIF(Matrice!$D$93:$D$99,"Natif")+COUNTIF(Matrice!$D$93:$D$99,"Officiel"))/(C30-COUNTIF(Matrice!$D$93:$D$99,"Info")),0) -> 1 | E30: =IFERROR((COUNTIF(Matrice!$E$93:$E$99,"Natif")+COUNTIF(Matrice!$E$93:$E$99,"Officiel"))/(C30-COUNTIF(Matrice!$E$93:$E$99,"Info")),0) -> 0.83333333 | F30: =IFERROR((COUNTIF(Matrice!$F$93:$F$99,"Natif")+COUNTIF(Matrice!$F$93:$F$99,"Officiel"))/(C30-COUNTIF(Matrice!$F$93:$F$99,"Info")),0) -> 0.5 | G30: =IFERROR((COUNTIF(Matrice!$G$93:$G$99,"Natif")+COUNTIF(Matrice!$G$93:$G$99,"Officiel"))/(C30-COUNTIF(Matrice!$G$93:$G$99,"Info")),0) -> 0.83333333 | H30: =IFERROR((COUNTIF(Matrice!$H$93:$H$99,"Natif")+COUNTIF(Matrice!$H$93:$H$99,"Officiel"))/(C30-COUNTIF(Matrice!$H$93:$H$99,"Info")),0) -> 0.66666667 | I30: =IFERROR((COUNTIF(Matrice!$I$93:$I$99,"Natif")+COUNTIF(Matrice!$I$93:$I$99,"Officiel"))/(C30-COUNTIF(Matrice!$I$93:$I$99,"Info")),0) -> 0.66666667 | J30: =IFERROR((COUNTIF(Matrice!$J$93:$J$99,"Natif")+COUNTIF(Matrice!$J$93:$J$99,"Officiel"))/(C30-COUNTIF(Matrice!$J$93:$J$99,"Info")),0) -> 0.83333333 | K30: =IFERROR((COUNTIF(Matrice!$K$93:$K$99,"Natif")+COUNTIF(Matrice!$K$93:$K$99,"Officiel"))/(C30-COUNTIF(Matrice!$K$93:$K$99,"Info")),0) -> 0 | L30: =IFERROR((COUNTIF(Matrice!$L$93:$L$99,"Natif")+COUNTIF(Matrice!$L$93:$L$99,"Officiel"))/(C30-COUNTIF(Matrice!$L$93:$L$99,"Info")),0) -> 0.83333333 | M30: =IFERROR((COUNTIF(Matrice!$M$93:$M$99,"Natif")+COUNTIF(Matrice!$M$93:$M$99,"Officiel"))/(C30-COUNTIF(Matrice!$M$93:$M$99,"Info")),0) -> 0.5
A31: Diffusion | B31: Thèmes et front-end | C31: 7 | D31: =IFERROR((COUNTIF(Matrice!$D$100:$D$106,"Natif")+COUNTIF(Matrice!$D$100:$D$106,"Officiel"))/(C31-COUNTIF(Matrice!$D$100:$D$106,"Info")),0) -> 0.71428571 | E31: =IFERROR((COUNTIF(Matrice!$E$100:$E$106,"Natif")+COUNTIF(Matrice!$E$100:$E$106,"Officiel"))/(C31-COUNTIF(Matrice!$E$100:$E$106,"Info")),0) -> 0.71428571 | F31: =IFERROR((COUNTIF(Matrice!$F$100:$F$106,"Natif")+COUNTIF(Matrice!$F$100:$F$106,"Officiel"))/(C31-COUNTIF(Matrice!$F$100:$F$106,"Info")),0) -> 0.28571429 | G31: =IFERROR((COUNTIF(Matrice!$G$100:$G$106,"Natif")+COUNTIF(Matrice!$G$100:$G$106,"Officiel"))/(C31-COUNTIF(Matrice!$G$100:$G$106,"Info")),0) -> 0.28571429 | H31: =IFERROR((COUNTIF(Matrice!$H$100:$H$106,"Natif")+COUNTIF(Matrice!$H$100:$H$106,"Officiel"))/(C31-COUNTIF(Matrice!$H$100:$H$106,"Info")),0) -> 0.57142857 | I31: =IFERROR((COUNTIF(Matrice!$I$100:$I$106,"Natif")+COUNTIF(Matrice!$I$100:$I$106,"Officiel"))/(C31-COUNTIF(Matrice!$I$100:$I$106,"Info")),0) -> 0.57142857 | J31: =IFERROR((COUNTIF(Matrice!$J$100:$J$106,"Natif")+COUNTIF(Matrice!$J$100:$J$106,"Officiel"))/(C31-COUNTIF(Matrice!$J$100:$J$106,"Info")),0) -> 0.85714286 | K31: =IFERROR((COUNTIF(Matrice!$K$100:$K$106,"Natif")+COUNTIF(Matrice!$K$100:$K$106,"Officiel"))/(C31-COUNTIF(Matrice!$K$100:$K$106,"Info")),0) -> 0.28571429 | L31: =IFERROR((COUNTIF(Matrice!$L$100:$L$106,"Natif")+COUNTIF(Matrice!$L$100:$L$106,"Officiel"))/(C31-COUNTIF(Matrice!$L$100:$L$106,"Info")),0) -> 0.71428571 | M31: =IFERROR((COUNTIF(Matrice!$M$100:$M$106,"Natif")+COUNTIF(Matrice!$M$100:$M$106,"Officiel"))/(C31-COUNTIF(Matrice!$M$100:$M$106,"Info")),0) -> 0.42857143
A32: Diffusion | B32: SEO | C32: 7 | D32: =IFERROR((COUNTIF(Matrice!$D$107:$D$113,"Natif")+COUNTIF(Matrice!$D$107:$D$113,"Officiel"))/(C32-COUNTIF(Matrice!$D$107:$D$113,"Info")),0) -> 0.42857143 | E32: =IFERROR((COUNTIF(Matrice!$E$107:$E$113,"Natif")+COUNTIF(Matrice!$E$107:$E$113,"Officiel"))/(C32-COUNTIF(Matrice!$E$107:$E$113,"Info")),0) -> 0 | F32: =IFERROR((COUNTIF(Matrice!$F$107:$F$113,"Natif")+COUNTIF(Matrice!$F$107:$F$113,"Officiel"))/(C32-COUNTIF(Matrice!$F$107:$F$113,"Info")),0) -> 0 | G32: =IFERROR((COUNTIF(Matrice!$G$107:$G$113,"Natif")+COUNTIF(Matrice!$G$107:$G$113,"Officiel"))/(C32-COUNTIF(Matrice!$G$107:$G$113,"Info")),0) -> 0 | H32: =IFERROR((COUNTIF(Matrice!$H$107:$H$113,"Natif")+COUNTIF(Matrice!$H$107:$H$113,"Officiel"))/(C32-COUNTIF(Matrice!$H$107:$H$113,"Info")),0) -> 0.85714286 | I32: =IFERROR((COUNTIF(Matrice!$I$107:$I$113,"Natif")+COUNTIF(Matrice!$I$107:$I$113,"Officiel"))/(C32-COUNTIF(Matrice!$I$107:$I$113,"Info")),0) -> 0.14285714 | J32: =IFERROR((COUNTIF(Matrice!$J$107:$J$113,"Natif")+COUNTIF(Matrice!$J$107:$J$113,"Officiel"))/(C32-COUNTIF(Matrice!$J$107:$J$113,"Info")),0) -> 0.85714286 | K32: =IFERROR((COUNTIF(Matrice!$K$107:$K$113,"Natif")+COUNTIF(Matrice!$K$107:$K$113,"Officiel"))/(C32-COUNTIF(Matrice!$K$107:$K$113,"Info")),0) -> 0.28571429 | L32: =IFERROR((COUNTIF(Matrice!$L$107:$L$113,"Natif")+COUNTIF(Matrice!$L$107:$L$113,"Officiel"))/(C32-COUNTIF(Matrice!$L$107:$L$113,"Info")),0) -> 0.71428571 | M32: =IFERROR((COUNTIF(Matrice!$M$107:$M$113,"Natif")+COUNTIF(Matrice!$M$107:$M$113,"Officiel"))/(C32-COUNTIF(Matrice!$M$107:$M$113,"Info")),0) -> 0.14285714
A33: Diffusion | B33: API et headless | C33: 8 | D33: =IFERROR((COUNTIF(Matrice!$D$114:$D$121,"Natif")+COUNTIF(Matrice!$D$114:$D$121,"Officiel"))/(C33-COUNTIF(Matrice!$D$114:$D$121,"Info")),0) -> 0.625 | E33: =IFERROR((COUNTIF(Matrice!$E$114:$E$121,"Natif")+COUNTIF(Matrice!$E$114:$E$121,"Officiel"))/(C33-COUNTIF(Matrice!$E$114:$E$121,"Info")),0) -> 0.75 | F33: =IFERROR((COUNTIF(Matrice!$F$114:$F$121,"Natif")+COUNTIF(Matrice!$F$114:$F$121,"Officiel"))/(C33-COUNTIF(Matrice!$F$114:$F$121,"Info")),0) -> 0.875 | G33: =IFERROR((COUNTIF(Matrice!$G$114:$G$121,"Natif")+COUNTIF(Matrice!$G$114:$G$121,"Officiel"))/(C33-COUNTIF(Matrice!$G$114:$G$121,"Info")),0) -> 0.375 | H33: =IFERROR((COUNTIF(Matrice!$H$114:$H$121,"Natif")+COUNTIF(Matrice!$H$114:$H$121,"Officiel"))/(C33-COUNTIF(Matrice!$H$114:$H$121,"Info")),0) -> 0.625 | I33: =IFERROR((COUNTIF(Matrice!$I$114:$I$121,"Natif")+COUNTIF(Matrice!$I$114:$I$121,"Officiel"))/(C33-COUNTIF(Matrice!$I$114:$I$121,"Info")),0) -> 0 | J33: =IFERROR((COUNTIF(Matrice!$J$114:$J$121,"Natif")+COUNTIF(Matrice!$J$114:$J$121,"Officiel"))/(C33-COUNTIF(Matrice!$J$114:$J$121,"Info")),0) -> 0.625 | K33: =IFERROR((COUNTIF(Matrice!$K$114:$K$121,"Natif")+COUNTIF(Matrice!$K$114:$K$121,"Officiel"))/(C33-COUNTIF(Matrice!$K$114:$K$121,"Info")),0) -> 0.875 | L33: =IFERROR((COUNTIF(Matrice!$L$114:$L$121,"Natif")+COUNTIF(Matrice!$L$114:$L$121,"Officiel"))/(C33-COUNTIF(Matrice!$L$114:$L$121,"Info")),0) -> 0.625 | M33: =IFERROR((COUNTIF(Matrice!$M$114:$M$121,"Natif")+COUNTIF(Matrice!$M$114:$M$121,"Officiel"))/(C33-COUNTIF(Matrice!$M$114:$M$121,"Info")),0) -> 0
A34: Diffusion | B34: Commerce | C34: 5 | D34: =IFERROR((COUNTIF(Matrice!$D$122:$D$126,"Natif")+COUNTIF(Matrice!$D$122:$D$126,"Officiel"))/(C34-COUNTIF(Matrice!$D$122:$D$126,"Info")),0) -> 0.8 | E34: =IFERROR((COUNTIF(Matrice!$E$122:$E$126,"Natif")+COUNTIF(Matrice!$E$122:$E$126,"Officiel"))/(C34-COUNTIF(Matrice!$E$122:$E$126,"Info")),0) -> 0 | F34: =IFERROR((COUNTIF(Matrice!$F$122:$F$126,"Natif")+COUNTIF(Matrice!$F$122:$F$126,"Officiel"))/(C34-COUNTIF(Matrice!$F$122:$F$126,"Info")),0) -> 0.8 | G34: =IFERROR((COUNTIF(Matrice!$G$122:$G$126,"Natif")+COUNTIF(Matrice!$G$122:$G$126,"Officiel"))/(C34-COUNTIF(Matrice!$G$122:$G$126,"Info")),0) -> 0 | H34: =IFERROR((COUNTIF(Matrice!$H$122:$H$126,"Natif")+COUNTIF(Matrice!$H$122:$H$126,"Officiel"))/(C34-COUNTIF(Matrice!$H$122:$H$126,"Info")),0) -> 0 | I34: =IFERROR((COUNTIF(Matrice!$I$122:$I$126,"Natif")+COUNTIF(Matrice!$I$122:$I$126,"Officiel"))/(C34-COUNTIF(Matrice!$I$122:$I$126,"Info")),0) -> 0.6 | J34: =IFERROR((COUNTIF(Matrice!$J$122:$J$126,"Natif")+COUNTIF(Matrice!$J$122:$J$126,"Officiel"))/(C34-COUNTIF(Matrice!$J$122:$J$126,"Info")),0) -> 0.6 | K34: =IFERROR((COUNTIF(Matrice!$K$122:$K$126,"Natif")+COUNTIF(Matrice!$K$122:$K$126,"Officiel"))/(C34-COUNTIF(Matrice!$K$122:$K$126,"Info")),0) -> 0.4 | L34: =IFERROR((COUNTIF(Matrice!$L$122:$L$126,"Natif")+COUNTIF(Matrice!$L$122:$L$126,"Officiel"))/(C34-COUNTIF(Matrice!$L$122:$L$126,"Info")),0) -> 0.2 | M34: =IFERROR((COUNTIF(Matrice!$M$122:$M$126,"Natif")+COUNTIF(Matrice!$M$122:$M$126,"Officiel"))/(C34-COUNTIF(Matrice!$M$122:$M$126,"Info")),0) -> 0
A35: Diffusion | B35: Accessibilité | C35: 4 | D35: =IFERROR((COUNTIF(Matrice!$D$127:$D$130,"Natif")+COUNTIF(Matrice!$D$127:$D$130,"Officiel"))/(C35-COUNTIF(Matrice!$D$127:$D$130,"Info")),0) -> 0.5 | E35: =IFERROR((COUNTIF(Matrice!$E$127:$E$130,"Natif")+COUNTIF(Matrice!$E$127:$E$130,"Officiel"))/(C35-COUNTIF(Matrice!$E$127:$E$130,"Info")),0) -> 0.75 | F35: =IFERROR((COUNTIF(Matrice!$F$127:$F$130,"Natif")+COUNTIF(Matrice!$F$127:$F$130,"Officiel"))/(C35-COUNTIF(Matrice!$F$127:$F$130,"Info")),0) -> 0.5 | G35: =IFERROR((COUNTIF(Matrice!$G$127:$G$130,"Natif")+COUNTIF(Matrice!$G$127:$G$130,"Officiel"))/(C35-COUNTIF(Matrice!$G$127:$G$130,"Info")),0) -> 0 | H35: =IFERROR((COUNTIF(Matrice!$H$127:$H$130,"Natif")+COUNTIF(Matrice!$H$127:$H$130,"Officiel"))/(C35-COUNTIF(Matrice!$H$127:$H$130,"Info")),0) -> 0 | I35: =IFERROR((COUNTIF(Matrice!$I$127:$I$130,"Natif")+COUNTIF(Matrice!$I$127:$I$130,"Officiel"))/(C35-COUNTIF(Matrice!$I$127:$I$130,"Info")),0) -> 0 | J35: =IFERROR((COUNTIF(Matrice!$J$127:$J$130,"Natif")+COUNTIF(Matrice!$J$127:$J$130,"Officiel"))/(C35-COUNTIF(Matrice!$J$127:$J$130,"Info")),0) -> 0 | K35: =IFERROR((COUNTIF(Matrice!$K$127:$K$130,"Natif")+COUNTIF(Matrice!$K$127:$K$130,"Officiel"))/(C35-COUNTIF(Matrice!$K$127:$K$130,"Info")),0) -> 0 | L35: =IFERROR((COUNTIF(Matrice!$L$127:$L$130,"Natif")+COUNTIF(Matrice!$L$127:$L$130,"Officiel"))/(C35-COUNTIF(Matrice!$L$127:$L$130,"Info")),0) -> 0 | M35: =IFERROR((COUNTIF(Matrice!$M$127:$M$130,"Natif")+COUNTIF(Matrice!$M$127:$M$130,"Officiel"))/(C35-COUNTIF(Matrice!$M$127:$M$130,"Info")),0) -> 0
A36: Technique | B36: Stockage des données | C36: 5 | D36: =IFERROR((COUNTIF(Matrice!$D$131:$D$135,"Natif")+COUNTIF(Matrice!$D$131:$D$135,"Officiel"))/(C36-COUNTIF(Matrice!$D$131:$D$135,"Info")),0) -> 0.25 | E36: =IFERROR((COUNTIF(Matrice!$E$131:$E$135,"Natif")+COUNTIF(Matrice!$E$131:$E$135,"Officiel"))/(C36-COUNTIF(Matrice!$E$131:$E$135,"Info")),0) -> 0.25 | F36: =IFERROR((COUNTIF(Matrice!$F$131:$F$135,"Natif")+COUNTIF(Matrice!$F$131:$F$135,"Officiel"))/(C36-COUNTIF(Matrice!$F$131:$F$135,"Info")),0) -> 0.25 | G36: =IFERROR((COUNTIF(Matrice!$G$131:$G$135,"Natif")+COUNTIF(Matrice!$G$131:$G$135,"Officiel"))/(C36-COUNTIF(Matrice!$G$131:$G$135,"Info")),0) -> 0.75 | H36: =IFERROR((COUNTIF(Matrice!$H$131:$H$135,"Natif")+COUNTIF(Matrice!$H$131:$H$135,"Officiel"))/(C36-COUNTIF(Matrice!$H$131:$H$135,"Info")),0) -> 1 | I36: =IFERROR((COUNTIF(Matrice!$I$131:$I$135,"Natif")+COUNTIF(Matrice!$I$131:$I$135,"Officiel"))/(C36-COUNTIF(Matrice!$I$131:$I$135,"Info")),0) -> 0.5 | J36: =IFERROR((COUNTIF(Matrice!$J$131:$J$135,"Natif")+COUNTIF(Matrice!$J$131:$J$135,"Officiel"))/(C36-COUNTIF(Matrice!$J$131:$J$135,"Info")),0) -> 0.5 | K36: =IFERROR((COUNTIF(Matrice!$K$131:$K$135,"Natif")+COUNTIF(Matrice!$K$131:$K$135,"Officiel"))/(C36-COUNTIF(Matrice!$K$131:$K$135,"Info")),0) -> 0.25 | L36: =IFERROR((COUNTIF(Matrice!$L$131:$L$135,"Natif")+COUNTIF(Matrice!$L$131:$L$135,"Officiel"))/(C36-COUNTIF(Matrice!$L$131:$L$135,"Info")),0) -> 0.25 | M36: =IFERROR((COUNTIF(Matrice!$M$131:$M$135,"Natif")+COUNTIF(Matrice!$M$131:$M$135,"Officiel"))/(C36-COUNTIF(Matrice!$M$131:$M$135,"Info")),0) -> 0.25
A37: Technique | B37: Configuration as code | C37: 4 | D37: =IFERROR((COUNTIF(Matrice!$D$136:$D$139,"Natif")+COUNTIF(Matrice!$D$136:$D$139,"Officiel"))/(C37-COUNTIF(Matrice!$D$136:$D$139,"Info")),0) -> 0.5 | E37: =IFERROR((COUNTIF(Matrice!$E$136:$E$139,"Natif")+COUNTIF(Matrice!$E$136:$E$139,"Officiel"))/(C37-COUNTIF(Matrice!$E$136:$E$139,"Info")),0) -> 0.75 | F37: =IFERROR((COUNTIF(Matrice!$F$136:$F$139,"Natif")+COUNTIF(Matrice!$F$136:$F$139,"Officiel"))/(C37-COUNTIF(Matrice!$F$136:$F$139,"Info")),0) -> 1 | G37: =IFERROR((COUNTIF(Matrice!$G$136:$G$139,"Natif")+COUNTIF(Matrice!$G$136:$G$139,"Officiel"))/(C37-COUNTIF(Matrice!$G$136:$G$139,"Info")),0) -> 0.75 | H37: =IFERROR((COUNTIF(Matrice!$H$136:$H$139,"Natif")+COUNTIF(Matrice!$H$136:$H$139,"Officiel"))/(C37-COUNTIF(Matrice!$H$136:$H$139,"Info")),0) -> 1 | I37: =IFERROR((COUNTIF(Matrice!$I$136:$I$139,"Natif")+COUNTIF(Matrice!$I$136:$I$139,"Officiel"))/(C37-COUNTIF(Matrice!$I$136:$I$139,"Info")),0) -> 0.5 | J37: =IFERROR((COUNTIF(Matrice!$J$136:$J$139,"Natif")+COUNTIF(Matrice!$J$136:$J$139,"Officiel"))/(C37-COUNTIF(Matrice!$J$136:$J$139,"Info")),0) -> 1 | K37: =IFERROR((COUNTIF(Matrice!$K$136:$K$139,"Natif")+COUNTIF(Matrice!$K$136:$K$139,"Officiel"))/(C37-COUNTIF(Matrice!$K$136:$K$139,"Info")),0) -> 1 | L37: =IFERROR((COUNTIF(Matrice!$L$136:$L$139,"Natif")+COUNTIF(Matrice!$L$136:$L$139,"Officiel"))/(C37-COUNTIF(Matrice!$L$136:$L$139,"Info")),0) -> 0.25 | M37: =IFERROR((COUNTIF(Matrice!$M$136:$M$139,"Natif")+COUNTIF(Matrice!$M$136:$M$139,"Officiel"))/(C37-COUNTIF(Matrice!$M$136:$M$139,"Info")),0) -> 0.25
A38: Technique | B38: Synchronisation entre environnements | C38: 4 | D38: =IFERROR((COUNTIF(Matrice!$D$140:$D$143,"Natif")+COUNTIF(Matrice!$D$140:$D$143,"Officiel"))/(C38-COUNTIF(Matrice!$D$140:$D$143,"Info")),0) -> 0 | E38: =IFERROR((COUNTIF(Matrice!$E$140:$E$143,"Natif")+COUNTIF(Matrice!$E$140:$E$143,"Officiel"))/(C38-COUNTIF(Matrice!$E$140:$E$143,"Info")),0) -> 0.75 | F38: =IFERROR((COUNTIF(Matrice!$F$140:$F$143,"Natif")+COUNTIF(Matrice!$F$140:$F$143,"Officiel"))/(C38-COUNTIF(Matrice!$F$140:$F$143,"Info")),0) -> 0.5 | G38: =IFERROR((COUNTIF(Matrice!$G$140:$G$143,"Natif")+COUNTIF(Matrice!$G$140:$G$143,"Officiel"))/(C38-COUNTIF(Matrice!$G$140:$G$143,"Info")),0) -> 0.25 | H38: =IFERROR((COUNTIF(Matrice!$H$140:$H$143,"Natif")+COUNTIF(Matrice!$H$140:$H$143,"Officiel"))/(C38-COUNTIF(Matrice!$H$140:$H$143,"Info")),0) -> 0.75 | I38: =IFERROR((COUNTIF(Matrice!$I$140:$I$143,"Natif")+COUNTIF(Matrice!$I$140:$I$143,"Officiel"))/(C38-COUNTIF(Matrice!$I$140:$I$143,"Info")),0) -> 0.25 | J38: =IFERROR((COUNTIF(Matrice!$J$140:$J$143,"Natif")+COUNTIF(Matrice!$J$140:$J$143,"Officiel"))/(C38-COUNTIF(Matrice!$J$140:$J$143,"Info")),0) -> 0.5 | K38: =IFERROR((COUNTIF(Matrice!$K$140:$K$143,"Natif")+COUNTIF(Matrice!$K$140:$K$143,"Officiel"))/(C38-COUNTIF(Matrice!$K$140:$K$143,"Info")),0) -> 0.5 | L38: =IFERROR((COUNTIF(Matrice!$L$140:$L$143,"Natif")+COUNTIF(Matrice!$L$140:$L$143,"Officiel"))/(C38-COUNTIF(Matrice!$L$140:$L$143,"Info")),0) -> 0.25 | M38: =IFERROR((COUNTIF(Matrice!$M$140:$M$143,"Natif")+COUNTIF(Matrice!$M$140:$M$143,"Officiel"))/(C38-COUNTIF(Matrice!$M$140:$M$143,"Info")),0) -> 0
A39: Technique | B39: Extensibilité | C39: 7 | D39: =IFERROR((COUNTIF(Matrice!$D$144:$D$150,"Natif")+COUNTIF(Matrice!$D$144:$D$150,"Officiel"))/(C39-COUNTIF(Matrice!$D$144:$D$150,"Info")),0) -> 1 | E39: =IFERROR((COUNTIF(Matrice!$E$144:$E$150,"Natif")+COUNTIF(Matrice!$E$144:$E$150,"Officiel"))/(C39-COUNTIF(Matrice!$E$144:$E$150,"Info")),0) -> 1 | F39: =IFERROR((COUNTIF(Matrice!$F$144:$F$150,"Natif")+COUNTIF(Matrice!$F$144:$F$150,"Officiel"))/(C39-COUNTIF(Matrice!$F$144:$F$150,"Info")),0) -> 1 | G39: =IFERROR((COUNTIF(Matrice!$G$144:$G$150,"Natif")+COUNTIF(Matrice!$G$144:$G$150,"Officiel"))/(C39-COUNTIF(Matrice!$G$144:$G$150,"Info")),0) -> 0.85714286 | H39: =IFERROR((COUNTIF(Matrice!$H$144:$H$150,"Natif")+COUNTIF(Matrice!$H$144:$H$150,"Officiel"))/(C39-COUNTIF(Matrice!$H$144:$H$150,"Info")),0) -> 1 | I39: =IFERROR((COUNTIF(Matrice!$I$144:$I$150,"Natif")+COUNTIF(Matrice!$I$144:$I$150,"Officiel"))/(C39-COUNTIF(Matrice!$I$144:$I$150,"Info")),0) -> 1 | J39: =IFERROR((COUNTIF(Matrice!$J$144:$J$150,"Natif")+COUNTIF(Matrice!$J$144:$J$150,"Officiel"))/(C39-COUNTIF(Matrice!$J$144:$J$150,"Info")),0) -> 1 | K39: =IFERROR((COUNTIF(Matrice!$K$144:$K$150,"Natif")+COUNTIF(Matrice!$K$144:$K$150,"Officiel"))/(C39-COUNTIF(Matrice!$K$144:$K$150,"Info")),0) -> 0.85714286 | L39: =IFERROR((COUNTIF(Matrice!$L$144:$L$150,"Natif")+COUNTIF(Matrice!$L$144:$L$150,"Officiel"))/(C39-COUNTIF(Matrice!$L$144:$L$150,"Info")),0) -> 0.85714286 | M39: =IFERROR((COUNTIF(Matrice!$M$144:$M$150,"Natif")+COUNTIF(Matrice!$M$144:$M$150,"Officiel"))/(C39-COUNTIF(Matrice!$M$144:$M$150,"Info")),0) -> 0.85714286
A40: Technique | B40: Performance et cache | C40: 7 | D40: =IFERROR((COUNTIF(Matrice!$D$151:$D$157,"Natif")+COUNTIF(Matrice!$D$151:$D$157,"Officiel"))/(C40-COUNTIF(Matrice!$D$151:$D$157,"Info")),0) -> 1 | E40: =IFERROR((COUNTIF(Matrice!$E$151:$E$157,"Natif")+COUNTIF(Matrice!$E$151:$E$157,"Officiel"))/(C40-COUNTIF(Matrice!$E$151:$E$157,"Info")),0) -> 0.71428571 | F40: =IFERROR((COUNTIF(Matrice!$F$151:$F$157,"Natif")+COUNTIF(Matrice!$F$151:$F$157,"Officiel"))/(C40-COUNTIF(Matrice!$F$151:$F$157,"Info")),0) -> 0.42857143 | G40: =IFERROR((COUNTIF(Matrice!$G$151:$G$157,"Natif")+COUNTIF(Matrice!$G$151:$G$157,"Officiel"))/(C40-COUNTIF(Matrice!$G$151:$G$157,"Info")),0) -> 0.42857143 | H40: =IFERROR((COUNTIF(Matrice!$H$151:$H$157,"Natif")+COUNTIF(Matrice!$H$151:$H$157,"Officiel"))/(C40-COUNTIF(Matrice!$H$151:$H$157,"Info")),0) -> 0.71428571 | I40: =IFERROR((COUNTIF(Matrice!$I$151:$I$157,"Natif")+COUNTIF(Matrice!$I$151:$I$157,"Officiel"))/(C40-COUNTIF(Matrice!$I$151:$I$157,"Info")),0) -> 0.28571429 | J40: =IFERROR((COUNTIF(Matrice!$J$151:$J$157,"Natif")+COUNTIF(Matrice!$J$151:$J$157,"Officiel"))/(C40-COUNTIF(Matrice!$J$151:$J$157,"Info")),0) -> 0.71428571 | K40: =IFERROR((COUNTIF(Matrice!$K$151:$K$157,"Natif")+COUNTIF(Matrice!$K$151:$K$157,"Officiel"))/(C40-COUNTIF(Matrice!$K$151:$K$157,"Info")),0) -> 0.14285714 | L40: =IFERROR((COUNTIF(Matrice!$L$151:$L$157,"Natif")+COUNTIF(Matrice!$L$151:$L$157,"Officiel"))/(C40-COUNTIF(Matrice!$L$151:$L$157,"Info")),0) -> 0.28571429 | M40: =IFERROR((COUNTIF(Matrice!$M$151:$M$157,"Natif")+COUNTIF(Matrice!$M$151:$M$157,"Officiel"))/(C40-COUNTIF(Matrice!$M$151:$M$157,"Info")),0) -> 0.14285714
A41: Technique | B41: Tâches planifiées et files d'attente | C41: 3 | D41: =IFERROR((COUNTIF(Matrice!$D$158:$D$160,"Natif")+COUNTIF(Matrice!$D$158:$D$160,"Officiel"))/(C41-COUNTIF(Matrice!$D$158:$D$160,"Info")),0) -> 0.66666667 | E41: =IFERROR((COUNTIF(Matrice!$E$158:$E$160,"Natif")+COUNTIF(Matrice!$E$158:$E$160,"Officiel"))/(C41-COUNTIF(Matrice!$E$158:$E$160,"Info")),0) -> 1 | F41: =IFERROR((COUNTIF(Matrice!$F$158:$F$160,"Natif")+COUNTIF(Matrice!$F$158:$F$160,"Officiel"))/(C41-COUNTIF(Matrice!$F$158:$F$160,"Info")),0) -> 0.66666667 | G41: =IFERROR((COUNTIF(Matrice!$G$158:$G$160,"Natif")+COUNTIF(Matrice!$G$158:$G$160,"Officiel"))/(C41-COUNTIF(Matrice!$G$158:$G$160,"Info")),0) -> 0 | H41: =IFERROR((COUNTIF(Matrice!$H$158:$H$160,"Natif")+COUNTIF(Matrice!$H$158:$H$160,"Officiel"))/(C41-COUNTIF(Matrice!$H$158:$H$160,"Info")),0) -> 1 | I41: =IFERROR((COUNTIF(Matrice!$I$158:$I$160,"Natif")+COUNTIF(Matrice!$I$158:$I$160,"Officiel"))/(C41-COUNTIF(Matrice!$I$158:$I$160,"Info")),0) -> 0.66666667 | J41: =IFERROR((COUNTIF(Matrice!$J$158:$J$160,"Natif")+COUNTIF(Matrice!$J$158:$J$160,"Officiel"))/(C41-COUNTIF(Matrice!$J$158:$J$160,"Info")),0) -> 0.33333333 | K41: =IFERROR((COUNTIF(Matrice!$K$158:$K$160,"Natif")+COUNTIF(Matrice!$K$158:$K$160,"Officiel"))/(C41-COUNTIF(Matrice!$K$158:$K$160,"Info")),0) -> 1 | L41: =IFERROR((COUNTIF(Matrice!$L$158:$L$160,"Natif")+COUNTIF(Matrice!$L$158:$L$160,"Officiel"))/(C41-COUNTIF(Matrice!$L$158:$L$160,"Info")),0) -> 1 | M41: =IFERROR((COUNTIF(Matrice!$M$158:$M$160,"Natif")+COUNTIF(Matrice!$M$158:$M$160,"Officiel"))/(C41-COUNTIF(Matrice!$M$158:$M$160,"Info")),0) -> 0.66666667
A42: Technique | B42: Sécurité | C42: 7 | D42: =IFERROR((COUNTIF(Matrice!$D$161:$D$167,"Natif")+COUNTIF(Matrice!$D$161:$D$167,"Officiel"))/(C42-COUNTIF(Matrice!$D$161:$D$167,"Info")),0) -> 0.71428571 | E42: =IFERROR((COUNTIF(Matrice!$E$161:$E$167,"Natif")+COUNTIF(Matrice!$E$161:$E$167,"Officiel"))/(C42-COUNTIF(Matrice!$E$161:$E$167,"Info")),0) -> 0.57142857 | F42: =IFERROR((COUNTIF(Matrice!$F$161:$F$167,"Natif")+COUNTIF(Matrice!$F$161:$F$167,"Officiel"))/(C42-COUNTIF(Matrice!$F$161:$F$167,"Info")),0) -> 0.57142857 | G42: =IFERROR((COUNTIF(Matrice!$G$161:$G$167,"Natif")+COUNTIF(Matrice!$G$161:$G$167,"Officiel"))/(C42-COUNTIF(Matrice!$G$161:$G$167,"Info")),0) -> 0.57142857 | H42: =IFERROR((COUNTIF(Matrice!$H$161:$H$167,"Natif")+COUNTIF(Matrice!$H$161:$H$167,"Officiel"))/(C42-COUNTIF(Matrice!$H$161:$H$167,"Info")),0) -> 0.71428571 | I42: =IFERROR((COUNTIF(Matrice!$I$161:$I$167,"Natif")+COUNTIF(Matrice!$I$161:$I$167,"Officiel"))/(C42-COUNTIF(Matrice!$I$161:$I$167,"Info")),0) -> 0.71428571 | J42: =IFERROR((COUNTIF(Matrice!$J$161:$J$167,"Natif")+COUNTIF(Matrice!$J$161:$J$167,"Officiel"))/(C42-COUNTIF(Matrice!$J$161:$J$167,"Info")),0) -> 0.71428571 | K42: =IFERROR((COUNTIF(Matrice!$K$161:$K$167,"Natif")+COUNTIF(Matrice!$K$161:$K$167,"Officiel"))/(C42-COUNTIF(Matrice!$K$161:$K$167,"Info")),0) -> 0.57142857 | L42: =IFERROR((COUNTIF(Matrice!$L$161:$L$167,"Natif")+COUNTIF(Matrice!$L$161:$L$167,"Officiel"))/(C42-COUNTIF(Matrice!$L$161:$L$167,"Info")),0) -> 0.42857143 | M42: =IFERROR((COUNTIF(Matrice!$M$161:$M$167,"Natif")+COUNTIF(Matrice!$M$161:$M$167,"Officiel"))/(C42-COUNTIF(Matrice!$M$161:$M$167,"Info")),0) -> 0.28571429
...

Sheet Priorisation
A1: Priorisation pour un CMS Laravel / Filament
A2: Proposition à valider. MVP = socle indispensable au lancement ; V1 = attendu par le marché ; V2 = plus tard ; Hors périmètre = écarté volontairement. Différenciant = peu couvert nativement par les 10 CMS et à forte valeur. « Couverture » = nombre de CMS sur 10 qui l'offrent en natif ou via extension officielle (formule vers la Matrice).
A4: Priorité | B4: Nb fonct. | C4: dont différenciantes
A5: MVP | B5: =COUNTIF($F$12:$F$2000,A5) -> 109 | C5: =COUNTIFS($F$12:$F$2000,A5,$G$12:$G$2000,"Oui") -> 17
A6: V1 | B6: =COUNTIF($F$12:$F$2000,A6) -> 123 | C6: =COUNTIFS($F$12:$F$2000,A6,$G$12:$G$2000,"Oui") -> 37
A7: V2 | B7: =COUNTIF($F$12:$F$2000,A7) -> 75 | C7: =COUNTIFS($F$12:$F$2000,A7,$G$12:$G$2000,"Oui") -> 25
A8: Hors périmètre | B8: =COUNTIF($F$12:$F$2000,A8) -> 26 | C8: =COUNTIFS($F$12:$F$2000,A8,$G$12:$G$2000,"Oui") -> 0
A9: Total | B9: =SUM(B5:B8) -> 333 | C9: =SUM(C5:C8) -> 79
A11: Bloc | B11: Catégorie | C11: Fonctionnalité | D11: Origine | E11: Couverture (/10) | F11: Priorité | G11: Différenciant | H11: Brique Laravel / Filament | I11: Vu chez (ajouts)
A12: Contenu | B12: Modélisation de contenu | C12: Types de contenu personnalisés (sans code) | D12: Grille | E12: =Matrice!O2 -> 4 | F12: V2 | H12: Générateur de schéma dans l'admin
A13: Contenu | B13: Modélisation de contenu | C13: Types de contenu définis en code (schéma versionnable) | D13: Grille | E13: =Matrice!O3 -> 8 | F13: MVP | H13: Classes PHP + migrations
A14: Contenu | B14: Modélisation de contenu | C14: Champs personnalisés (bibliothèque de types de champs) | D14: Grille | E14: =Matrice!O4 -> 8 | F14: MVP | H14: Champs Filament Forms
A15: Contenu | B15: Modélisation de contenu | C15: Champs répétables / groupes de champs | D15: Grille | E15: =Matrice!O5 -> 7 | F15: MVP | H15: Filament Repeater
A16: Contenu | B16: Modélisation de contenu | C16: Relations entre contenus (1-n, n-n) | D16: Grille | E16: =Matrice!O6 -> 7 | F16: MVP | H16: Relations Eloquent + Filament Select/RelationManager
A17: Contenu | B17: Modélisation de contenu | C17: Relations bidirectionnelles / reverse lookup | D17: Grille | E17: =Matrice!O7 -> 3 | F17: V1 | G17: Oui | H17: Relations inverses Eloquent
A18: Contenu | B18: Modélisation de contenu | C18: Taxonomies (catégories, tags, vocabulaires personnalisés) | D18: Grille | E18: =Matrice!O8 -> 6 | F18: MVP | H18: spatie/laravel-tags ou modèles dédiés
A19: Contenu | B19: Modélisation de contenu | C19: Contenu hiérarchique (arborescence parent/enfant) | D19: Grille | E19: =Matrice!O9 -> 9 | F19: MVP | H19: kalnoy/nestedset ou adjacency list
A20: Contenu | B20: Modélisation de contenu | C20: Ensembles de champs réutilisables (fieldsets / blueprints) | D20: Grille | E20: =Matrice!O10 -> 7 | F20: MVP | H20: Méthodes de schéma Filament réutilisables
A21: Contenu | B21: Modélisation de contenu | C21: Contenus globaux / singletons (réglages de site) | D21: Grille | E21: =Matrice!O11 -> 8 | F21: MVP | H21: spatie/laravel-settings + Filament Settings
A22: Contenu | B22: Modélisation de contenu | C22: Validation des champs (règles, champs obligatoires) | D22: Grille | E22: =Matrice!O12 -> 10 | F22: MVP | H22: Validation Laravel (natif Filament)
A23: Contenu | B23: Modélisation de contenu | C23: Champs conditionnels (affichage selon valeur) | D23: Grille | E23: =Matrice!O13 -> 6 | F23: MVP | H23: Filament visible() / live() (natif)
A24: Contenu | B24: Modélisation de contenu | C24: Champs calculés / dérivés | D24: Grille | E24: =Matrice!O14 -> 3 | F24: V1 | H24: Filament afterStateUpdated / accessors Eloquent
A25: Contenu | B25: Modélisation de contenu | C25: Constructeur de listes / requêtes sans code (pages, blocs, flux) | D25: Ajout (hors grille) | F25: V2 | G25: Oui | H25: Filament Table + query builder | I25: Drupal (Views), WordPress (Query Loop)
A26: Contenu | B26: Modélisation de contenu | C26: Cascade d'héritage des données et valeurs par défaut (globales → section → entrée) | D26: Ajout (hors grille) | F26: V1 | H26: Logique applicative | I26: Statamic, TallCMS
A27: Contenu | B27: Modélisation de contenu | C27: Format de titre automatique / titres générés | D27: Ajout (hors grille) | F27: V1 | H27: Mutators Eloquent | I27: Craft, Statamic
A28: Contenu | B28: Modélisation de contenu | C28: Dictionnaires : listes d'options issues de sources externes | D28: Ajout (hors grille) | F28: V2 | H28: Filament Select options() | I28: Statamic
A29: Contenu | B29: Modélisation de contenu | C29: Contenu virtuel issu de sources externes (API, autre base) | D29: Ajout (hors grille) | F29: V2 | H29: Eloquent / Sushi | I29: Kirby
A30: Contenu | B30: Modélisation de contenu | C30: UUID et liens internes stables (résistent aux renommages) | D30: Ajout (hors grille) | F30: MVP | H30: HasUuids Eloquent | I30: Kirby, Craft
A31: Contenu | B31: Modélisation de contenu | C31: Modes d'affichage multiples par type (carte, liste, complet) | D31: Ajout (hors grille) | F31: V1 | H31: Vues Blade par mode | I31: Drupal
A32: Contenu | B32: Modélisation de contenu | C32: Champs spécialisés : adresse, lien multi-type, couleur, icône, montant, JSON/code | D32: Ajout (hors grille) | F32: V1 | H32: Champs Filament + plugins | I32: Craft, Payload, Kirby
A33: Contenu | B33: Modélisation de contenu | C33: Champs de géolocalisation avec requêtes de proximité | D33: Ajout (hors grille) | F33: V2 | H33: Plugin carte Filament + requêtes spatiales | I33: Payload, Drupal (contrib)
A34: Contenu | B34: Modélisation de contenu | C34: Champs de mise en page (onglets, sections, colonnes) | D34: Ajout (hors grille) | F34: MVP | H34: Filament Tabs / Section / Grid (natif) | I34: Payload, Statamic
A35: Contenu | B35: Modélisation de contenu | C35: Ordre manuel par glisser-déposer | D35: Ajout (hors grille) | F35: MVP | H35: Filament reorderable() + eloquent-sortable | I35: Payload, Statamic
A36: Contenu | B36: Modélisation de contenu | C36: Plusieurs types d'entrée dans une même section | D36: Ajout (hors grille) | F36: V1 | H36: Single table + type | I36: Craft, October
A37: Contenu | B37: Modélisation de contenu | C37: Classe PHP dédiée par type de contenu (méthodes métier) | D37: Ajout (hors grille) | F37: MVP | H37: Modèles Eloquent | I37: Kirby, Drupal
... A39: Contenu | B39: Modélisation de contenu | C39: Outils de refactor de schéma (fusion, nettoyage, réenregistrement en masse) | D39: Ajout (hors grille) | F39: V2 | H39: Commandes Artisan | I39: Craft, October
A40: Contenu | B40: Édition et blocs | C40: Éditeur WYSIWYG / rich text | D40: Grille | E40: =Matrice!O15 -> 10 | F40: MVP | H40: Filament RichEditor (TipTap)
A41: Contenu | B41: Édition et blocs | C41: Éditeur par blocs (block editor / page builder) | D41: Grille | E41: =Matrice!O16 -> 8 | F41: MVP | H41: Filament Builder
A42: Contenu | B42: Édition et blocs | C42: Blocs personnalisés définis par le développeur | D42: Grille | E42: =Matrice!O17 -> 9 | F42: MVP | H42: Filament Builder\Block
A43: Contenu | B43: Édition et blocs | C43: Blocs imbriqués | D43: Grille | E43: =Matrice!O18 -> 7 | F43: V1 | H43: Builder dans Builder
...

Sheet Matrice
A1: Bloc | B1: Catégorie | C1: Fonctionnalité | D1: WordPress | E1: Drupal | F1: Craft CMS | G1: Kirby | H1: Statamic | I1: October CMS | J1: Grav | K1: Payload | L1: TallCMS | M1: Lara Zeus Sky | N1: Nb natif | O1: Nb dispo (natif+officiel)
A2: Contenu | B2: Modélisation de contenu | C2: Types de contenu personnalisés (sans code) | D2: Officiel | E2: Natif | F2: Natif | G2: Absent | H2: Natif | I2: Partiel | J2: Partiel | K2: Absent | L2: Absent | M2: Absent | N2: =COUNTIF(D2:M2,"Natif") -> 3 | O2: =COUNTIF(D2:M2,"Natif")+COUNTIF(D2:M2,"Officiel") -> 4
A3: Contenu | B3: Modélisation de contenu | C3: Types de contenu définis en code (schéma versionnable) | D3: Natif | E3: Natif | F3: Natif | G3: Natif | H3: Natif | I3: Natif | J3: Natif | K3: Natif | L3: Partiel | M3: Partiel | N3: =COUNTIF(D3:M3,"Natif") -> 8 | O3: =COUNTIF(D3:M3,"Natif")+COUNTIF(D3:M3,"Officiel") -> 8
A4: Contenu | B4: Modélisation de contenu | C4: Champs personnalisés (bibliothèque de types de champs) | D4: Officiel | E4: Natif | F4: Natif | G4: Natif | H4: Natif | I4: Natif | J4: Natif | K4: Natif | L4: Partiel | M4: Absent | N4: =COUNTIF(D4:M4,"Natif") -> 7 | O4: =COUNTIF(D4:M4,"Natif")+COUNTIF(D4:M4,"Officiel") -> 8
A5: Contenu | B5: Modélisation de contenu | C5: Champs répétables / groupes de champs | D5: Officiel | E5: Tiers | F5: Natif | G5: Natif | H5: Natif | I5: Natif | J5: Natif | K5: Natif | L5: Partiel | M5: Absent | N5: =COUNTIF(D5:M5,"Natif") -> 6 | O5: =COUNTIF(D5:M5,"Natif")+COUNTIF(D5:M5,"Officiel") -> 7
A6: Contenu | B6: Modélisation de contenu | C6: Relations entre contenus (1-n, n-n) | D6: Officiel | E6: Natif | F6: Natif | G6: Natif | H6: Natif | I6: Natif | J6: Partiel | K6: Natif | L6: Partiel | M6: Partiel | N6: =COUNTIF(D6:M6,"Natif") -> 6 | O6: =COUNTIF(D6:M6,"Natif")+COUNTIF(D6:M6,"Officiel") -> 7
A7: Contenu | B7: Modélisation de contenu | C7: Relations bidirectionnelles / reverse lookup | D7: Officiel | E7: Partiel | F7: Partiel | G7: Partiel | H7: Tiers | I7: Natif | J7: Absent | K7: Natif | L7: Partiel | M7: Partiel | N7: =COUNTIF(D7:M7,"Natif") -> 2 | O7: =COUNTIF(D7:M7,"Natif")+COUNTIF(D7:M7,"Officiel") -> 3
A8: Contenu | B8: Modélisation de contenu | C8: Taxonomies (catégories, tags, vocabulaires personnalisés) | D8: Natif | E8: Natif | F8: Natif | G8: Partiel | H8: Natif | I8: Partiel | J8: Natif | K8: Partiel | L8: Partiel | M8: Natif | N8: =COUNTIF(D8:M8,"Natif") -> 6 | O8: =COUNTIF(D8:M8,"Natif")+COUNTIF(D8:M8,"Officiel") -> 6
A9: Contenu | B9: Modélisation de contenu | C9: Contenu hiérarchique (arborescence parent/enfant) | D9: Natif | E9: Partiel | F9: Natif | G9: Natif | H9: Natif | I9: Natif | J9: Natif | K9: Officiel | L9: Natif | M9: Natif | N9: =COUNTIF(D9:M9,"Natif") -> 8 | O9: =COUNTIF(D9:M9,"Natif")+COUNTIF(D9:M9,"Officiel") -> 9
A10: Contenu | B10: Modélisation de contenu | C10: Ensembles de champs réutilisables (fieldsets / blueprints) | D10: Officiel | E10: Partiel | F10: Natif | G10: Natif | H10: Natif | I10: Natif | J10: Natif | K10: Natif | L10: Absent | M10: Absent | N10: =COUNTIF(D10:M10,"Natif") -> 6 | O10: =COUNTIF(D10:M10,"Natif")+COUNTIF(D10:M10,"Officiel") -> 7
A11: Contenu | B11: Modélisation de contenu | C11: Contenus globaux / singletons (réglages de site) | D11: Officiel | E11: Partiel | F11: Natif | G11: Natif | H11: Natif | I11: Natif | J11: Natif | K11: Natif | L11: Natif | M11: Partiel | N11: =COUNTIF(D11:M11,"Natif") -> 7 | O11: =COUNTIF(D11:M11,"Natif")+COUNTIF(D11:M11,"Officiel") -> 8
A12: Contenu | B12: Modélisation de contenu | C12: Validation des champs (règles, champs obligatoires) | D12: Officiel | E12: Natif | F12: Natif | G12: Natif | H12: Natif | I12: Natif | J12: Natif | K12: Natif | L12: Natif | M12: Natif | N12: =COUNTIF(D12:M12,"Natif") -> 9 | O12: =COUNTIF(D12:M12,"Natif")+COUNTIF(D12:M12,"Officiel") -> 10
A13: Contenu | B13: Modélisation de contenu | C13: Champs conditionnels (affichage selon valeur) | D13: Officiel | E13: Tiers | F13: Natif | G13: Partiel | H13: Natif | I13: Natif | J13: Partiel | K13: Natif | L13: Natif | M13: Partiel | N13: =COUNTIF(D13:M13,"Natif") -> 5 | O13: =COUNTIF(D13:M13,"Natif")+COUNTIF(D13:M13,"Officiel") -> 6
... A212: Gouvernance | B212: Écosystème et communauté | C212: Taille de la communauté (forum, Discord) | D212: Info | E212: Info | F212: Info | G212: Info | H212: Info | I212: Info | J212: Info | K212: Info | L212: Info | M212: Info | N212: =COUNTIF(D212:M212,"Natif") -> 0 | O212: =COUNTIF(D212:M212,"Natif")+COUNTIF(D212:M212,"Officiel") -> 0

Sheet Détails
A1: Bloc | B1: Catégorie | C1: Fonctionnalité | D1: CMS | E1: Statut | F1: Détail | G1: Source
A2: Contenu | B2: Modélisation de contenu | C2: Types de contenu personnalisés (sans code) | D2: WordPress | E2: Officiel | F2: Secure Custom Fields (plugin WordPress.org, gratuit) permet d'enregistrer types de contenu et taxonomies via l'admin ; le cœur l'exige en code. | G2: https://wordpress.org/plugins/secure-custom-fields/
A3: Contenu | B3: Modélisation de contenu | C3: Types de contenu personnalisés (sans code) | D3: Drupal | E3: Natif | F3: Types de contenu (bundles de nœuds) créés et configurés depuis Structure > Types de contenu. | G3: https://www.drupal.org/docs/user_guide/en/structure-content-type.html
A4: Contenu | B4: Modélisation de contenu | C4: Types de contenu personnalisés (sans code) | D4: Craft CMS | E4: Natif | F4: Sections (Single, Channel, Structure) et types d'entrées globaux créés depuis Paramètres, sans code. | G4: https://craftcms.com/docs/5.x/reference/element-types/entries.html
